<?xml version="1.0"?>
<robot xmlns:xacro="http://www.ros.org/wiki/xacro" name="curt_mini">

  <!-- path to package -->
  <xacro:arg name="path" default="$(find curt_mini)" />
  <xacro:arg name="use_sim_time" default="False" />
  <xacro:arg name="gazebo_controllers" default="$(arg path)/config/ros2_control_simulation.yaml" />
  <xacro:arg name="simulation" default="False" />
  <xacro:arg name="prefix" default=""/>

  <!-- Import ros2_control -->
  <xacro:include filename="$(find curt_mini)/models/curt_mini/ros2_control.xacro" />

  <!-- Include properties -->
  <xacro:include filename="$(find curt_mini)/models/curt_mini/properties.xacro" />

  <!-- Include sensors -->
  <xacro:include filename="$(find curt_mini)/models/curt_mini/sensors.xacro" />

  <link name="$(arg prefix)base_link" />

  <!-- Chassis link at same position as base_link, as root is not allowed to have inertial
  information -->
  <link name="$(arg prefix)chassis">
    <inertial>
      <origin xyz="0.011876 0.003999 0.048645" rpy="0 0 0" />
      <mass value="9.0318" />
      <inertia ixx="0.04558" ixy="-2.4654E-05" ixz="0.0014869" iyy="0.059986" iyz="2.4934E-05"
        izz="0.09132" />
    </inertial>
    <visual>
      <origin xyz="0 0 0" rpy="0 0 0" />
      <geometry>
        <mesh filename="file://$(arg path)/models/curt_mini/meshes/base_link.STL" />
      </geometry>
      <material name="">
        <color rgba="0.79216 0.81961 0.93333 1" />
      </material>
    </visual>
    <collision>
      <origin xyz="0 0 0" rpy="0 0 0" />
      <geometry>
        <mesh filename="file://$(arg path)/models/curt_mini/meshes/base_link.STL" />
      </geometry>
    </collision>
  </link>
  <joint name="base_to_chassis" type="fixed">
    <parent link="$(arg prefix)base_link" />
    <child link="$(arg prefix)chassis" />
  </joint>

  <link name="$(arg prefix)front_right_wheel">
    <inertial>
      <origin xyz="-2.8086E-05 0.013016 2.8089E-05" rpy="0 0 0" />
      <mass value="0.61321" />
      <inertia ixx="0.0031957" ixy="-6.9366E-08" ixz="-8.7949E-07" iyy="0.0057902" iyz="6.9371E-08"
        izz="0.0031957" />
    </inertial>
    <visual>
      <origin xyz="0 0 0" rpy="0 0 0" />
      <geometry>
        <mesh filename="file://$(arg path)/models/curt_mini/meshes/wheel4_link.STL" />
      </geometry>
      <material name="">
        <color rgba="0.79216 0.81961 0.93333 1" />
      </material>
    </visual>
    <collision>
      <origin xyz="0 0.01 0" rpy="${PI / 2} 0 0" />
      <geometry>
        <cylinder radius="${wheel_radius}" length="${wheel_width}" />
      </geometry>
    </collision>
  </link>
  <joint name="front_right_motor" type="continuous">
    <origin xyz="0.25995 -0.258 -0.030204" rpy="0 0 0" />
    <parent link="$(arg prefix)base_link" />
    <child link="$(arg prefix)front_right_wheel" />
    <axis xyz="0 1 0" />
    <dynamics damping="1.0" />
    <limit effort="${max_effort}" velocity="${max_wheel_velocity}" />
  </joint>

  <link name="$(arg prefix)front_left_wheel">
    <inertial>
      <origin xyz="2.8086E-05 -0.013016 2.8089E-05" rpy="0 0 0" />
      <mass value="0.61321" />
      <inertia ixx="0.0031957" ixy="-6.9366E-08" ixz="8.7949E-07" iyy="0.0057902" iyz="-6.9371E-08"
        izz="0.0031957" />
    </inertial>
    <visual>
      <origin xyz="0 0 0" rpy="0 0 0" />
      <geometry>
        <mesh filename="file://$(arg path)/models/curt_mini/meshes/wheel1_link.STL" />
      </geometry>
      <material name="">
        <color rgba="0.79216 0.81961 0.93333 1" />
      </material>
    </visual>
    <collision>
      <origin xyz="0 -0.01 0" rpy="${PI / 2} 0 0" />
      <geometry>
        <cylinder radius="${wheel_radius}" length="${wheel_width}" />
      </geometry>
    </collision>
  </link>
  <joint name="front_left_motor" type="continuous">
    <origin xyz="0.25995 0.258 -0.030204" rpy="0 0 0" />
    <parent link="$(arg prefix)base_link" />
    <child link="$(arg prefix)front_left_wheel" />
    <axis xyz="0 1 0" />
    <dynamics damping="1.0" />
    <limit effort="${max_effort}" velocity="${max_wheel_velocity}" />
  </joint>

  <link name="$(arg prefix)back_right_wheel">
    <inertial>
      <origin xyz="-2.8086E-05 0.013016 2.8089E-05" rpy="0 0 0" />
      <mass value="0.61321" />
      <inertia ixx="0.0031957" ixy="-6.9366E-08" ixz="-8.7949E-07" iyy="0.0057902" iyz="6.9371E-08"
        izz="0.0031957" />
    </inertial>
    <visual>
      <origin xyz="0 0 0" rpy="0 0 0" />
      <geometry>
        <mesh filename="file://$(arg path)/models/curt_mini/meshes/wheel3_link.STL" />
      </geometry>
      <material name="">
        <color rgba="0.79216 0.81961 0.93333 1" />
      </material>
    </visual>
    <collision>
      <origin xyz="0 0.01 0" rpy="${PI / 2} 0 0" />
      <geometry>
        <cylinder radius="${wheel_radius}" length="${wheel_width}" />
      </geometry>
    </collision>
  </link>
  <joint name="back_right_motor" type="continuous">
    <origin xyz="-0.26 -0.258 -0.022755" rpy="0 0 0" />
    <parent link="$(arg prefix)base_link" />
    <child link="$(arg prefix)back_right_wheel" />
    <axis xyz="0 1 0" />
    <dynamics damping="1.0" />
    <limit effort="${max_effort}" velocity="${max_wheel_velocity}" />
  </joint>

  <link name="$(arg prefix)back_left_wheel">
    <inertial>
      <origin xyz="2.8086E-05 -0.013016 2.8089E-05" rpy="0 0 0" />
      <mass value="0.61321" />
      <inertia ixx="0.0031957" ixy="-6.9366E-08" ixz="8.7949E-07" iyy="0.0057902" iyz="-6.9371E-08"
        izz="0.0031957" />
    </inertial>
    <visual>
      <origin xyz="0 0 0" rpy="0 0 0" />
      <geometry>
        <mesh filename="file://$(arg path)/models/curt_mini/meshes/wheel2_link.STL" />
      </geometry>
      <material name="">
        <color rgba="0.79216 0.81961 0.93333 1" />
      </material>
    </visual>
    <collision>
      <origin xyz="0 -0.01 0" rpy="${PI / 2} 0 0" />
      <geometry>
        <cylinder radius="${wheel_radius}" length="${wheel_width}" />
      </geometry>
    </collision>
  </link>
  <joint name="back_left_motor" type="continuous">
    <origin xyz="-0.26 0.258 -0.022755" rpy="0 0 0" />
    <parent link="$(arg prefix)base_link" />
    <child link="$(arg prefix)back_left_wheel" />
    <axis xyz="0 1 0" />
    <dynamics damping="1.0" />
    <limit effort="${max_effort}" velocity="${max_wheel_velocity}" />
  </joint>

  <!-- Import gazebo infos -->
  <xacro:if value="$(arg simulation)">
    <xacro:include filename="$(find curt_mini)/models/curt_mini/gazebo.xacro" />
  </xacro:if>

</robot>